Workbook

Sheet 1. PASTE DATA
A1: 1. PASTE DATA
A2: One student per row, from row 4 to row 1503. Headers must match exactly. Grey columns on the right calculate themselves — do not type in them.
A3: School | B3: Student Name | C3: Class | D3: Section | E3: Gender | F3: Speed and accuracy | G3: Computational | H3: Creativity | I3: Communication | J3: Technical | K3: Decision making & problem solving | L3: Finger dexterity | M3: Form perception | N3: Logical reasoning | O3: Motor movement | P3: Bodily-Kinesthetic | Q3: Interpersonal | R3: Intrapersonal | S3: Linguistic | T3: Logical-Mathematical | U3: Musical | V3: Visual-Spatial | W3: Naturalistic | X3: Realistic | Y3: Investigative | Z3: Artistic | AA3: Social | AB3: Enterprising | AC3: Conventional | AD3: Personality_Top1 | AE3: Personality_Top2 | AF3: Personality_Top3 | AG3: Value 1 | AH3: Value 2 | AI3: Value 3 | AJ3: Value 4 | AK3: Value 5 | AL3: Career Aspiration 1 | AM3: Career Aspiration 2 | AN3: Career Aspiration 3 | AO3: Career Aspiration 4 | AP3: suitability_index_1 | AQ3: suitability_index_2 | AR3: suitability_index_3 | AS3: suitability_index_4 | AT3: suitability_index_5 | AU3: suitability_index_6 | AV3: suitability_index_7 | AW3: suitability_index_8 | AX3: suitability_index_9 | AZ3: » Matched aspirations | BA3: » Has a match | BB3: » Suitability #1 stream | BC3: » Top aspiration stream | BD3: » Abilities 10+ | BE3: » Abilities 8-
AZ4: =IF($B4="","",SUMPRODUCT(($AL4:$AO4<>"")*(COUNTIF($AP4:$AX4,$AL4:$AO4)>0))) | BA4: =IF($B4="","",IF(AZ4>0,1,0)) | BB4: =IF($AP4="","",IF((($AP4="Engineering and Technology")+($AP4="Science and Mathematics")+($AP4="Computer Science, IT and Allied Fields")+($AP4="Life Sciences /Medicine and Healthcare")+($AP4="Paramedical")+($AP4="Architecture")+($AP4="Environmental Service")+($AP4="Agriculture, Food Industry and Forestry"))>0,"Science",IF((($AP4="Banking and Finance")+($AP4="Management and Administration")+($AP4="Marketing")+($AP4="Sales")+($AP4="Entrepreneurship")+($AP4="Hospitality and Tourism"))>0,"Commerce",IF((($AP4="Social Sciences and Humanities")+($AP4="Law Studies")+($AP4="Education and Training")+($AP4="Art, Design")+($AP4="Entertainment and Mass Media")+($AP4="Community and Social Service")+($AP4="Personal Care and Services")+($AP4="Government and Public Administration")+($AP4="Defence/ Protective Service")+($AP4="Sports"))>0,"Arts / Humanities","")))) | BC4: =IF($AL4="","",IF((($AL4="Engineering and Technology")+($AL4="Science and Mathematics")+($AL4="Computer Science, IT and Allied Fields")+($AL4="Life Sciences /Medicine and Healthcare")+($AL4="Paramedical")+($AL4="Architecture")+($AL4="Environmental Service")+($AL4="Agriculture, Food Industry and Forestry"))>0,"Science",IF((($AL4="Banking and Finance")+($AL4="Management and Administration")+($AL4="Marketing")+($AL4="Sales")+($AL4="Entrepreneurship")+($AL4="Hospitality and Tourism"))>0,"Commerce",IF((($AL4="Social Sciences and Humanities")+($AL4="Law Studies")+($AL4="Education and Training")+($AL4="Art, Design")+($AL4="Entertainment and Mass Media")+($AL4="Community and Social Service")+($AL4="Personal Care and Services")+($AL4="Government and Public Administration")+($AL4="Defence/ Protective Service")+($AL4="Sports"))>0,"Arts / Humanities","")))) | BD4: =IF($B4="","",--(F4>=10)+--(G4>=10)+--(H4>=10)+--(I4>=10)+--(J4>=10)+--(K4>=10)+--(L4>=10)+--(M4>=10)+--(N4>=10)+--(O4>=10)) | BE4: =IF($B4="","",--(AND(F4<>"",F4<=8))+--(AND(G4<>"",G4<=8))+--(AND(H4<>"",H4<=8))+--(AND(I4<>"",I4<=8))+--(AND(J4<>"",J4<=8))+--(AND(K4<>"",K4<=8))+--(AND(L4<>"",L4<=8))+--(AND(M4<>"",M4<=8))+--(AND(N4<>"",N4<=8))+--(AND(O4<>"",O4<=8)))
AZ5: =IF($B5="","",SUMPRODUCT(($AL5:$AO5<>"")*(COUNTIF($AP5:$AX5,$AL5:$AO5)>0))) | BA5: =IF($B5="","",IF(AZ5>0,1,0)) | BB5: =IF($AP5="","",IF((($AP5="Engineering and Technology")+($AP5="Science and Mathematics")+($AP5="Computer Science, IT and Allied Fields")+($AP5="Life Sciences /Medicine and Healthcare")+($AP5="Paramedical")+($AP5="Architecture")+($AP5="Environmental Service")+($AP5="Agriculture, Food Industry and Forestry"))>0,"Science",IF((($AP5="Banking and Finance")+($AP5="Management and Administration")+($AP5="Marketing")+($AP5="Sales")+($AP5="Entrepreneurship")+($AP5="Hospitality and Tourism"))>0,"Commerce",IF((($AP5="Social Sciences and Humanities")+($AP5="Law Studies")+($AP5="Education and Training")+($AP5="Art, Design")+($AP5="Entertainment and Mass Media")+($AP5="Community and Social Service")+($AP5="Personal Care and Services")+($AP5="Government and Public Administration")+($AP5="Defence/ Protective Service")+($AP5="Sports"))>0,"Arts / Humanities","")))) | BC5: =IF($AL5="","",IF((($AL5="Engineering and Technology")+($AL5="Science and Mathematics")+($AL5="Computer Science, IT and Allied Fields")+($AL5="Life Sciences /Medicine and Healthcare")+($AL5="Paramedical")+($AL5="Architecture")+($AL5="Environmental Service")+($AL5="Agriculture, Food Industry and Forestry"))>0,"Science",IF((($AL5="Banking and Finance")+($AL5="Management and Administration")+($AL5="Marketing")+($AL5="Sales")+($AL5="Entrepreneurship")+($AL5="Hospitality and Tourism"))>0,"Commerce",IF((($AL5="Social Sciences and Humanities")+($AL5="Law Studies")+($AL5="Education and Training")+($AL5="Art, Design")+($AL5="Entertainment and Mass Media")+($AL5="Community and Social Service")+($AL5="Personal Care and Services")+($AL5="Government and Public Administration")+($AL5="Defence/ Protective Service")+($AL5="Sports"))>0,"Arts / Humanities","")))) | BD5: =IF($B5="","",--(F5>=10)+--(G5>=10)+--(H5>=10)+--(I5>=10)+--(J5>=10)+--(K5>=10)+--(L5>=10)+--(M5>=10)+--(N5>=10)+--(O5>=10)) | BE5: =IF($B5="","",--(AND(F5<>"",F5<=8))+--(AND(G5<>"",G5<=8))+--(AND(H5<>"",H5<=8))+--(AND(I5<>"",I5<=8))+--(AND(J5<>"",J5<=8))+--(AND(K5<>"",K5<=8))+--(AND(L5<>"",L5<=8))+--(AND(M5<>"",M5<=8))+--(AND(N5<>"",N5<=8))+--(AND(O5<>"",O5<=8)))
AZ6: =IF($B6="","",SUMPRODUCT(($AL6:$AO6<>"")*(COUNTIF($AP6:$AX6,$AL6:$AO6)>0))) | BA6: =IF($B6="","",IF(AZ6>0,1,0)) | BB6: =IF($AP6="","",IF((($AP6="Engineering and Technology")+($AP6="Science and Mathematics")+($AP6="Computer Science, IT and Allied Fields")+($AP6="Life Sciences /Medicine and Healthcare")+($AP6="Paramedical")+($AP6="Architecture")+($AP6="Environmental Service")+($AP6="Agriculture, Food Industry and Forestry"))>0,"Science",IF((($AP6="Banking and Finance")+($AP6="Management and Administration")+($AP6="Marketing")+($AP6="Sales")+($AP6="Entrepreneurship")+($AP6="Hospitality and Tourism"))>0,"Commerce",IF((($AP6="Social Sciences and Humanities")+($AP6="Law Studies")+($AP6="Education and Training")+($AP6="Art, Design")+($AP6="Entertainment and Mass Media")+($AP6="Community and Social Service")+($AP6="Personal Care and Services")+($AP6="Government and Public Administration")+($AP6="Defence/ Protective Service")+($AP6="Sports"))>0,"Arts / Humanities","")))) | BC6: =IF($AL6="","",IF((($AL6="Engineering and Technology")+($AL6="Science and Mathematics")+($AL6="Computer Science, IT and Allied Fields")+($AL6="Life Sciences /Medicine and Healthcare")+($AL6="Paramedical")+($AL6="Architecture")+($AL6="Environmental Service")+($AL6="Agriculture, Food Industry and Forestry"))>0,"Science",IF((($AL6="Banking and Finance")+($AL6="Management and Administration")+($AL6="Marketing")+($AL6="Sales")+($AL6="Entrepreneurship")+($AL6="Hospitality and Tourism"))>0,"Commerce",IF((($AL6="Social Sciences and Humanities")+($AL6="Law Studies")+($AL6="Education and Training")+($AL6="Art, Design")+($AL6="Entertainment and Mass Media")+($AL6="Community and Social Service")+($AL6="Personal Care and Services")+($AL6="Government and Public Administration")+($AL6="Defence/ Protective Service")+($AL6="Sports"))>0,"Arts / Humanities","")))) | BD6: =IF($B6="","",--(F6>=10)+--(G6>=10)+--(H6>=10)+--(I6>=10)+--(J6>=10)+--(K6>=10)+--(L6>=10)+--(M6>=10)+--(N6>=10)+--(O6>=10)) | BE6: =IF($B6="","",--(AND(F6<>"",F6<=8))+--(AND(G6<>"",G6<=8))+--(AND(H6<>"",H6<=8))+--(AND(I6<>"",I6<=8))+--(AND(J6<>"",J6<=8))+--(AND(K6<>"",K6<=8))+--(AND(L6<>"",L6<=8))+--(AND(M6<>"",M6<=8))+--(AND(N6<>"",N6<=8))+--(AND(O6<>"",O6<=8)))
AZ7: =IF($B7="","",SUMPRODUCT(($AL7:$AO7<>"")*(COUNTIF($AP7:$AX7,$AL7:$AO7)>0))) | BA7: =IF($B7="","",IF(AZ7>0,1,0)) | BB7: =IF($AP7="","",IF((($AP7="Engineering and Technology")+($AP7="Science and Mathematics")+($AP7="Computer Science, IT and Allied Fields")+($AP7="Life Sciences /Medicine and Healthcare")+($AP7="Paramedical")+($AP7="Architecture")+($AP7="Environmental Service")+($AP7="Agriculture, Food Industry and Forestry"))>0,"Science",IF((($AP7="Banking and Finance")+($AP7="Management and Administration")+($AP7="Marketing")+($AP7="Sales")+($AP7="Entrepreneurship")+($AP7="Hospitality and Tourism"))>0,"Commerce",IF((($AP7="Social Sciences and Humanities")+($AP7="Law Studies")+($AP7="Education and Training")+($AP7="Art, Design")+($AP7="Entertainment and Mass Media")+($AP7="Community and Social Service")+($AP7="Personal Care and Services")+($AP7="Government and Public Administration")+($AP7="Defence/ Protective Service")+($AP7="Sports"))>0,"Arts / Humanities","")))) | BC7: =IF($AL7="","",IF((($AL7="Engineering and Technology")+($AL7="Science and Mathematics")+($AL7="Computer Science, IT and Allied Fields")+($AL7="Life Sciences /Medicine and Healthcare")+($AL7="Paramedical")+($AL7="Architecture")+($AL7="Environmental Service")+($AL7="Agriculture, Food Industry and Forestry"))>0,"Science",IF((($AL7="Banking and Finance")+($AL7="Management and Administration")+($AL7="Marketing")+($AL7="Sales")+($AL7="Entrepreneurship")+($AL7="Hospitality and Tourism"))>0,"Commerce",IF((($AL7="Social Sciences and Humanities")+($AL7="Law Studies")+($AL7="Education and Training")+($AL7="Art, Design")+($AL7="Entertainment and Mass Media")+($AL7="Community and Social Service")+($AL7="Personal Care and Services")+($AL7="Government and Public Administration")+($AL7="Defence/ Protective Service")+($AL7="Sports"))>0,"Arts / Humanities","")))) | BD7: =IF($B7="","",--(F7>=10)+--(G7>=10)+--(H7>=10)+--(I7>=10)+--(J7>=10)+--(K7>=10)+--(L7>=10)+--(M7>=10)+--(N7>=10)+--(O7>=10)) | BE7: =IF($B7="","",--(AND(F7<>"",F7<=8))+--(AND(G7<>"",G7<=8))+--(AND(H7<>"",H7<=8))+--(AND(I7<>"",I7<=8))+--(AND(J7<>"",J7<=8))+--(AND(K7<>"",K7<=8))+--(AND(L7<>"",L7<=8))+--(AND(M7<>"",M7<=8))+--(AND(N7<>"",N7<=8))+--(AND(O7<>"",O7<=8)))
AZ8: =IF($B8="","",SUMPRODUCT(($AL8:$AO8<>"")*(COUNTIF($AP8:$AX8,$AL8:$AO8)>0))) | BA8: =IF($B8="","",IF(AZ8>0,1,0)) | BB8: =IF($AP8="","",IF((($AP8="Engineering and Technology")+($AP8="Science and Mathematics")+($AP8="Computer Science, IT and Allied Fields")+($AP8="Life Sciences /Medicine and Healthcare")+($AP8="Paramedical")+($AP8="Architecture")+($AP8="Environmental Service")+($AP8="Agriculture, Food Industry and Forestry"))>0,"Science",IF((($AP8="Banking and Finance")+($AP8="Management and Administration")+($AP8="Marketing")+($AP8="Sales")+($AP8="Entrepreneurship")+($AP8="Hospitality and Tourism"))>0,"Commerce",IF((($AP8="Social Sciences and Humanities")+($AP8="Law Studies")+($AP8="Education and Training")+($AP8="Art, Design")+($AP8="Entertainment and Mass Media")+($AP8="Community and Social Service")+($AP8="Personal Care and Services")+($AP8="Government and Public Administration")+($AP8="Defence/ Protective Service")+($AP8="Sports"))>0,"Arts / Humanities","")))) | BC8: =IF($AL8="","",IF((($AL8="Engineering and Technology")+($AL8="Science and Mathematics")+($AL8="Computer Science, IT and Allied Fields")+($AL8="Life Sciences /Medicine and Healthcare")+($AL8="Paramedical")+($AL8="Architecture")+($AL8="Environmental Service")+($AL8="Agriculture, Food Industry and Forestry"))>0,"Science",IF((($AL8="Banking and Finance")+($AL8="Management and Administration")+($AL8="Marketing")+($AL8="Sales")+($AL8="Entrepreneurship")+($AL8="Hospitality and Tourism"))>0,"Commerce",IF((($AL8="Social Sciences and Humanities")+($AL8="Law Studies")+($AL8="Education and Training")+($AL8="Art, Design")+($AL8="Entertainment and Mass Media")+($AL8="Community and Social Service")+($AL8="Personal Care and Services")+($AL8="Government and Public Administration")+($AL8="Defence/ Protective Service")+($AL8="Sports"))>0,"Arts / Humanities","")))) | BD8: =IF($B8="","",--(F8>=10)+--(G8>=10)+--(H8>=10)+--(I8>=10)+--(J8>=10)+--(K8>=10)+--(L8>=10)+--(M8>=10)+--(N8>=10)+--(O8>=10)) | BE8: =IF($B8="","",--(AND(F8<>"",F8<=8))+--(AND(G8<>"",G8<=8))+--(AND(H8<>"",H8<=8))+--(AND(I8<>"",I8<=8))+--(AND(J8<>"",J8<=8))+--(AND(K8<>"",K8<=8))+--(AND(L8<>"",L8<=8))+--(AND(M8<>"",M8<=8))+--(AND(N8<>"",N8<=8))+--(AND(O8<>"",O8<=8)))
AZ9: =IF($B9="","",SUMPRODUCT(($AL9:$AO9<>"")*(COUNTIF($AP9:$AX9,$AL9:$AO9)>0))) | BA9: =IF($B9="","",IF(AZ9>0,1,0)) | BB9: =IF($AP9="","",IF((($AP9="Engineering and Technology")+($AP9="Science and Mathematics")+($AP9="Computer Science, IT and Allied Fields")+($AP9="Life Sciences /Medicine and Healthcare")+($AP9="Paramedical")+($AP9="Architecture")+($AP9="Environmental Service")+($AP9="Agriculture, Food Industry and Forestry"))>0,"Science",IF((($AP9="Banking and Finance")+($AP9="Management and Administration")+($AP9="Marketing")+($AP9="Sales")+($AP9="Entrepreneurship")+($AP9="Hospitality and Tourism"))>0,"Commerce",IF((($AP9="Social Sciences and Humanities")+($AP9="Law Studies")+($AP9="Education and Training")+($AP9="Art, Design")+($AP9="Entertainment and Mass Media")+($AP9="Community and Social Service")+($AP9="Personal Care and Services")+($AP9="Government and Public Administration")+($AP9="Defence/ Protective Service")+($AP9="Sports"))>0,"Arts / Humanities","")))) | BC9: =IF($AL9="","",IF((($AL9="Engineering and Technology")+($AL9="Science and Mathematics")+($AL9="Computer Science, IT and Allied Fields")+($AL9="Life Sciences /Medicine and Healthcare")+($AL9="Paramedical")+($AL9="Architecture")+($AL9="Environmental Service")+($AL9="Agriculture, Food Industry and Forestry"))>0,"Science",IF((($AL9="Banking and Finance")+($AL9="Management and Administration")+($AL9="Marketing")+($AL9="Sales")+($AL9="Entrepreneurship")+($AL9="Hospitality and Tourism"))>0,"Commerce",IF((($AL9="Social Sciences and Humanities")+($AL9="Law Studies")+($AL9="Education and Training")+($AL9="Art, Design")+($AL9="Entertainment and Mass Media")+($AL9="Community and Social Service")+($AL9="Personal Care and Services")+($AL9="Government and Public Administration")+($AL9="Defence/ Protective Service")+($AL9="Sports"))>0,"Arts / Humanities","")))) | BD9: =IF($B9="","",--(F9>=10)+--(G9>=10)+--(H9>=10)+--(I9>=10)+--(J9>=10)+--(K9>=10)+--(L9>=10)+--(M9>=10)+--(N9>=10)+--(O9>=10)) | BE9: =IF($B9="","",--(AND(F9<>"",F9<=8))+--(AND(G9<>"",G9<=8))+--(AND(H9<>"",H9<=8))+--(AND(I9<>"",I9<=8))+--(AND(J9<>"",J9<=8))+--(AND(K9<>"",K9<=8))+--(AND(L9<>"",L9<=8))+--(AND(M9<>"",M9<=8))+--(AND(N9<>"",N9<=8))+--(AND(O9<>"",O9<=8)))
AZ10: =IF($B10="","",SUMPRODUCT(($AL10:$AO10<>"")*(COUNTIF($AP10:$AX10,$AL10:$AO10)>0))) | BA10: =IF($B10="","",IF(AZ10>0,1,0)) | BB10: =IF($AP10="","",IF((($AP10="Engineering and Technology")+($AP10="Science and Mathematics")+($AP10="Computer Science, IT and Allied Fields")+($AP10="Life Sciences /Medicine and Healthcare")+($AP10="Paramedical")+($AP10="Architecture")+($AP10="Environmental Service")+($AP10="Agriculture, Food Industry and Forestry"))>0,"Science",IF((($AP10="Banking and Finance")+($AP10="Management and Administration")+($AP10="Marketing")+($AP10="Sales")+($AP10="Entrepreneurship")+($AP10="Hospitality and Tourism"))>0,"Commerce",IF((($AP10="Social Sciences and Humanities")+($AP10="Law Studies")+($AP10="Education and Training")+($AP10="Art, Design")+($AP10="Entertainment and Mass Media")+($AP10="Community and Social Service")+($AP10="Personal Care and Services")+($AP10="Government and Public Administration")+($AP10="Defence/ Protective Service")+($AP10="Sports"))>0,"Arts / Humanities","")))) | BC10: =IF($AL10="","",IF((($AL10="Engineering and Technology")+($AL10="Science and Mathematics")+($AL10="Computer Science, IT and Allied Fields")+($AL10="Life Sciences /Medicine and Healthcare")+($AL10="Paramedical")+($AL10="Architecture")+($AL10="Environmental Service")+($AL10="Agriculture, Food Industry and Forestry"))>0,"Science",IF((($AL10="Banking and Finance")+($AL10="Management and Administration")+($AL10="Marketing")+($AL10="Sales")+($AL10="Entrepreneurship")+($AL10="Hospitality and Tourism"))>0,"Commerce",IF((($AL10="Social Sciences and Humanities")+($AL10="Law Studies")+($AL10="Education and Training")+($AL10="Art, Design")+($AL10="Entertainment and Mass Media")+($AL10="Community and Social Service")+($AL10="Personal Care and Services")+($AL10="Government and Public Administration")+($AL10="Defence/ Protective Service")+($AL10="Sports"))>0,"Arts / Humanities","")))) | BD10: =IF($B10="","",--(F10>=10)+--(G10>=10)+--(H10>=10)+--(I10>=10)+--(J10>=10)+--(K10>=10)+--(L10>=10)+--(M10>=10)+--(N10>=10)+--(O10>=10)) | BE10: =IF($B10="","",--(AND(F10<>"",F10<=8))+--(AND(G10<>"",G10<=8))+--(AND(H10<>"",H10<=8))+--(AND(I10<>"",I10<=8))+--(AND(J10<>"",J10<=8))+--(AND(K10<>"",K10<=8))+--(AND(L10<>"",L10<=8))+--(AND(M10<>"",M10<=8))+--(AND(N10<>"",N10<=8))+--(AND(O10<>"",O10<=8)))
AZ11: =IF($B11="","",SUMPRODUCT(($AL11:$AO11<>"")*(COUNTIF($AP11:$AX11,$AL11:$AO11)>0))) | BA11: =IF($B11="","",IF(AZ11>0,1,0)) | BB11: =IF($AP11="","",IF((($AP11="Engineering and Technology")+($AP11="Science and Mathematics")+($AP11="Computer Science, IT and Allied Fields")+($AP11="Life Sciences /Medicine and Healthcare")+($AP11="Paramedical")+($AP11="Architecture")+($AP11="Environmental Service")+($AP11="Agriculture, Food Industry and Forestry"))>0,"Science",IF((($AP11="Banking and Finance")+($AP11="Management and Administration")+($AP11="Marketing")+($AP11="Sales")+($AP11="Entrepreneurship")+($AP11="Hospitality and Tourism"))>0,"Commerce",IF((($AP11="Social Sciences and Humanities")+($AP11="Law Studies")+($AP11="Education and Training")+($AP11="Art, Design")+($AP11="Entertainment and Mass Media")+($AP11="Community and Social Service")+($AP11="Personal Care and Services")+($AP11="Government and Public Administration")+($AP11="Defence/ Protective Service")+($AP11="Sports"))>0,"Arts / Humanities","")))) | BC11: =IF($AL11="","",IF((($AL11="Engineering and Technology")+($AL11="Science and Mathematics")+($AL11="Computer Science, IT and Allied Fields")+($AL11="Life Sciences /Medicine and Healthcare")+($AL11="Paramedical")+($AL11="Architecture")+($AL11="Environmental Service")+($AL11="Agriculture, Food Industry and Forestry"))>0,"Science",IF((($AL11="Banking and Finance")+($AL11="Management and Administration")+($AL11="Marketing")+($AL11="Sales")+($AL11="Entrepreneurship")+($AL11="Hospitality and Tourism"))>0,"Commerce",IF((($AL11="Social Sciences and Humanities")+($AL11="Law Studies")+($AL11="Education and Training")+($AL11="Art, Design")+($AL11="Entertainment and Mass Media")+($AL11="Community and Social Service")+($AL11="Personal Care and Services")+($AL11="Government and Public Administration")+($AL11="Defence/ Protective Service")+($AL11="Sports"))>0,"Arts / Humanities","")))) | BD11: =IF($B11="","",--(F11>=10)+--(G11>=10)+--(H11>=10)+--(I11>=10)+--(J11>=10)+--(K11>=10)+--(L11>=10)+--(M11>=10)+--(N11>=10)+--(O11>=10)) | BE11: =IF($B11="","",--(AND(F11<>"",F11<=8))+--(AND(G11<>"",G11<=8))+--(AND(H11<>"",H11<=8))+--(AND(I11<>"",I11<=8))+--(AND(J11<>"",J11<=8))+--(AND(K11<>"",K11<=8))+--(AND(L11<>"",L11<=8))+--(AND(M11<>"",M11<=8))+--(AND(N11<>"",N11<=8))+--(AND(O11<>"",O11<=8)))
AZ12: =IF($B12="","",SUMPRODUCT(($AL12:$AO12<>"")*(COUNTIF($AP12:$AX12,$AL12:$AO12)>0))) | BA12: =IF($B12="","",IF(AZ12>0,1,0)) | BB12: =IF($AP12="","",IF((($AP12="Engineering and Technology")+($AP12="Science and Mathematics")+($AP12="Computer Science, IT and Allied Fields")+($AP12="Life Sciences /Medicine and Healthcare")+($AP12="Paramedical")+($AP12="Architecture")+($AP12="Environmental Service")+($AP12="Agriculture, Food Industry and Forestry"))>0,"Science",IF((($AP12="Banking and Finance")+($AP12="Management and Administration")+($AP12="Marketing")+($AP12="Sales")+($AP12="Entrepreneurship")+($AP12="Hospitality and Tourism"))>0,"Commerce",IF((($AP12="Social Sciences and Humanities")+($AP12="Law Studies")+($AP12="Education and Training")+($AP12="Art, Design")+($AP12="Entertainment and Mass Media")+($AP12="Community and Social Service")+($AP12="Personal Care and Services")+($AP12="Government and Public Administration")+($AP12="Defence/ Protective Service")+($AP12="Sports"))>0,"Arts / Humanities","")))) | BC12: =IF($AL12="","",IF((($AL12="Engineering and Technology")+($AL12="Science and Mathematics")+($AL12="Computer Science, IT and Allied Fields")+($AL12="Life Sciences /Medicine and Healthcare")+($AL12="Paramedical")+($AL12="Architecture")+($AL12="Environmental Service")+($AL12="Agriculture, Food Industry and Forestry"))>0,"Science",IF((($AL12="Banking and Finance")+($AL12="Management and Administration")+($AL12="Marketing")+($AL12="Sales")+($AL12="Entrepreneurship")+($AL12="Hospitality and Tourism"))>0,"Commerce",IF((($AL12="Social Sciences and Humanities")+($AL12="Law Studies")+($AL12="Education and Training")+($AL12="Art, Design")+($AL12="Entertainment and Mass Media")+($AL12="Community and Social Service")+($AL12="Personal Care and Services")+($AL12="Government and Public Administration")+($AL12="Defence/ Protective Service")+($AL12="Sports"))>0,"Arts / Humanities","")))) | BD12: =IF($B12="","",--(F12>=10)+--(G12>=10)+--(H12>=10)+--(I12>=10)+--(J12>=10)+--(K12>=10)+--(L12>=10)+--(M12>=10)+--(N12>=10)+--(O12>=10)) | BE12: =IF($B12="","",--(AND(F12<>"",F12<=8))+--(AND(G12<>"",G12<=8))+--(AND(H12<>"",H12<=8))+--(AND(I12<>"",I12<=8))+--(AND(J12<>"",J12<=8))+--(AND(K12<>"",K12<=8))+--(AND(L12<>"",L12<=8))+--(AND(M12<>"",M12<=8))+--(AND(N12<>"",N12<=8))+--(AND(O12<>"",O12<=8)))
AZ13: =IF($B13="","",SUMPRODUCT(($AL13:$AO13<>"")*(COUNTIF($AP13:$AX13,$AL13:$AO13)>0))) | BA13: =IF($B13="","",IF(AZ13>0,1,0)) | BB13: =IF($AP13="","",IF((($AP13="Engineering and Technology")+($AP13="Science and Mathematics")+($AP13="Computer Science, IT and Allied Fields")+($AP13="Life Sciences /Medicine and Healthcare")+($AP13="Paramedical")+($AP13="Architecture")+($AP13="Environmental Service")+($AP13="Agriculture, Food Industry and Forestry"))>0,"Science",IF((($AP13="Banking and Finance")+($AP13="Management and Administration")+($AP13="Marketing")+($AP13="Sales")+($AP13="Entrepreneurship")+($AP13="Hospitality and Tourism"))>0,"Commerce",IF((($AP13="Social Sciences and Humanities")+($AP13="Law Studies")+($AP13="Education and Training")+($AP13="Art, Design")+($AP13="Entertainment and Mass Media")+($AP13="Community and Social Service")+($AP13="Personal Care and Services")+($AP13="Government and Public Administration")+($AP13="Defence/ Protective Service")+($AP13="Sports"))>0,"Arts / Humanities","")))) | BC13: =IF($AL13="","",IF((($AL13="Engineering and Technology")+($AL13="Science and Mathematics")+($AL13="Computer Science, IT and Allied Fields")+($AL13="Life Sciences /Medicine and Healthcare")+($AL13="Paramedical")+($AL13="Architecture")+($AL13="Environmental Service")+($AL13="Agriculture, Food Industry and Forestry"))>0,"Science",IF((($AL13="Banking and Finance")+($AL13="Management and Administration")+($AL13="Marketing")+($AL13="Sales")+($AL13="Entrepreneurship")+($AL13="Hospitality and Tourism"))>0,"Commerce",IF((($AL13="Social Sciences and Humanities")+($AL13="Law Studies")+($AL13="Education and Training")+($AL13="Art, Design")+($AL13="Entertainment and Mass Media")+($AL13="Community and Social Service")+($AL13="Personal Care and Services")+($AL13="Government and Public Administration")+($AL13="Defence/ Protective Service")+($AL13="Sports"))>0,"Arts / Humanities","")))) | BD13: =IF($B13="","",--(F13>=10)+--(G13>=10)+--(H13>=10)+--(I13>=10)+--(J13>=10)+--(K13>=10)+--(L13>=10)+--(M13>=10)+--(N13>=10)+--(O13>=10)) | BE13: =IF($B13="","",--(AND(F13<>"",F13<=8))+--(AND(G13<>"",G13<=8))+--(AND(H13<>"",H13<=8))+--(AND(I13<>"",I13<=8))+--(AND(J13<>"",J13<=8))+--(AND(K13<>"",K13<=8))+--(AND(L13<>"",L13<=8))+--(AND(M13<>"",M13<=8))+--(AND(N13<>"",N13<=8))+--(AND(O13<>"",O13<=8)))
AZ14: =IF($B14="","",SUMPRODUCT(($AL14:$AO14<>"")*(COUNTIF($AP14:$AX14,$AL14:$AO14)>0))) | BA14: =IF($B14="","",IF(AZ14>0,1,0)) | BB14: =IF($AP14="","",IF((($AP14="Engineering and Technology")+($AP14="Science and Mathematics")+($AP14="Computer Science, IT and Allied Fields")+($AP14="Life Sciences /Medicine and Healthcare")+($AP14="Paramedical")+($AP14="Architecture")+($AP14="Environmental Service")+($AP14="Agriculture, Food Industry and Forestry"))>0,"Science",IF((($AP14="Banking and Finance")+($AP14="Management and Administration")+($AP14="Marketing")+($AP14="Sales")+($AP14="Entrepreneurship")+($AP14="Hospitality and Tourism"))>0,"Commerce",IF((($AP14="Social Sciences and Humanities")+($AP14="Law Studies")+($AP14="Education and Training")+($AP14="Art, Design")+($AP14="Entertainment and Mass Media")+($AP14="Community and Social Service")+($AP14="Personal Care and Services")+($AP14="Government and Public Administration")+($AP14="Defence/ Protective Service")+($AP14="Sports"))>0,"Arts / Humanities","")))) | BC14: =IF($AL14="","",IF((($AL14="Engineering and Technology")+($AL14="Science and Mathematics")+($AL14="Computer Science, IT and Allied Fields")+($AL14="Life Sciences /Medicine and Healthcare")+($AL14="Paramedical")+($AL14="Architecture")+($AL14="Environmental Service")+($AL14="Agriculture, Food Industry and Forestry"))>0,"Science",IF((($AL14="Banking and Finance")+($AL14="Management and Administration")+($AL14="Marketing")+($AL14="Sales")+($AL14="Entrepreneurship")+($AL14="Hospitality and Tourism"))>0,"Commerce",IF((($AL14="Social Sciences and Humanities")+($AL14="Law Studies")+($AL14="Education and Training")+($AL14="Art, Design")+($AL14="Entertainment and Mass Media")+($AL14="Community and Social Service")+($AL14="Personal Care and Services")+($AL14="Government and Public Administration")+($AL14="Defence/ Protective Service")+($AL14="Sports"))>0,"Arts / Humanities","")))) | BD14: =IF($B14="","",--(F14>=10)+--(G14>=10)+--(H14>=10)+--(I14>=10)+--(J14>=10)+--(K14>=10)+--(L14>=10)+--(M14>=10)+--(N14>=10)+--(O14>=10)) | BE14: =IF($B14="","",--(AND(F14<>"",F14<=8))+--(AND(G14<>"",G14<=8))+--(AND(H14<>"",H14<=8))+--(AND(I14<>"",I14<=8))+--(AND(J14<>"",J14<=8))+--(AND(K14<>"",K14<=8))+--(AND(L14<>"",L14<=8))+--(AND(M14<>"",M14<=8))+--(AND(N14<>"",N14<=8))+--(AND(O14<>"",O14<=8)))
AZ15: =IF($B15="","",SUMPRODUCT(($AL15:$AO15<>"")*(COUNTIF($AP15:$AX15,$AL15:$AO15)>0))) | BA15: =IF($B15="","",IF(AZ15>0,1,0)) | BB15: =IF($AP15="","",IF((($AP15="Engineering and Technology")+($AP15="Science and Mathematics")+($AP15="Computer Science, IT and Allied Fields")+($AP15="Life Sciences /Medicine and Healthcare")+($AP15="Paramedical")+($AP15="Architecture")+($AP15="Environmental Service")+($AP15="Agriculture, Food Industry and Forestry"))>0,"Science",IF((($AP15="Banking and Finance")+($AP15="Management and Administration")+($AP15="Marketing")+($AP15="Sales")+($AP15="Entrepreneurship")+($AP15="Hospitality and Tourism"))>0,"Commerce",IF((($AP15="Social Sciences and Humanities")+($AP15="Law Studies")+($AP15="Education and Training")+($AP15="Art, Design")+($AP15="Entertainment and Mass Media")+($AP15="Community and Social Service")+($AP15="Personal Care and Services")+($AP15="Government and Public Administration")+($AP15="Defence/ Protective Service")+($AP15="Sports"))>0,"Arts / Humanities","")))) | BC15: =IF($AL15="","",IF((($AL15="Engineering and Technology")+($AL15="Science and Mathematics")+($AL15="Computer Science, IT and Allied Fields")+($AL15="Life Sciences /Medicine and Healthcare")+($AL15="Paramedical")+($AL15="Architecture")+($AL15="Environmental Service")+($AL15="Agriculture, Food Industry and Forestry"))>0,"Science",IF((($AL15="Banking and Finance")+($AL15="Management and Administration")+($AL15="Marketing")+($AL15="Sales")+($AL15="Entrepreneurship")+($AL15="Hospitality and Tourism"))>0,"Commerce",IF((($AL15="Social Sciences and Humanities")+($AL15="Law Studies")+($AL15="Education and Training")+($AL15="Art, Design")+($AL15="Entertainment and Mass Media")+($AL15="Community and Social Service")+($AL15="Personal Care and Services")+($AL15="Government and Public Administration")+($AL15="Defence/ Protective Service")+($AL15="Sports"))>0,"Arts / Humanities","")))) | BD15: =IF($B15="","",--(F15>=10)+--(G15>=10)+--(H15>=10)+--(I15>=10)+--(J15>=10)+--(K15>=10)+--(L15>=10)+--(M15>=10)+--(N15>=10)+--(O15>=10)) | BE15: =IF($B15="","",--(AND(F15<>"",F15<=8))+--(AND(G15<>"",G15<=8))+--(AND(H15<>"",H15<=8))+--(AND(I15<>"",I15<=8))+--(AND(J15<>"",J15<=8))+--(AND(K15<>"",K15<=8))+--(AND(L15<>"",L15<=8))+--(AND(M15<>"",M15<=8))+--(AND(N15<>"",N15<=8))+--(AND(O15<>"",O15<=8)))
... AZ1503: =IF($B1503="","",SUMPRODUCT(($AL1503:$AO1503<>"")*(COUNTIF($AP1503:$AX1503,$AL1503:$AO1503)>0))) | BA1503: =IF($B1503="","",IF(AZ1503>0,1,0)) | BB1503: =IF($AP1503="","",IF((($AP1503="Engineering and Technology")+($AP1503="Science and Mathematics")+($AP1503="Computer Science, IT and Allied Fields")+($AP1503="Life Sciences /Medicine and Healthcare")+($AP1503="Paramedical")+($AP1503="Architecture")+($AP1503="Environmental Service")+($AP1503="Agriculture, Food Industry and Forestry"))>0,"Science",IF((($AP1503="Banking and Finance")+($AP1503="Management and Administration")+($AP1503="Marketing")+($AP1503="Sales")+($AP1503="Entrepreneurship")+($AP1503="Hospitality and Tourism"))>0,"Commerce",IF((($AP1503="Social Sciences and Humanities")+($AP1503="Law Studies")+($AP1503="Education and Training")+($AP1503="Art, Design")+($AP1503="Entertainment and Mass Media")+($AP1503="Community and Social Service")+($AP1503="Personal Care and Services")+($AP1503="Government and Public Administration")+($AP1503="Defence/ Protective Service")+($AP1503="Sports"))>0,"Arts / Humanities","")))) | BC1503: =IF($AL1503="","",IF((($AL1503="Engineering and Technology")+($AL1503="Science and Mathematics")+($AL1503="Computer Science, IT and Allied Fields")+($AL1503="Life Sciences /Medicine and Healthcare")+($AL1503="Paramedical")+($AL1503="Architecture")+($AL1503="Environmental Service")+($AL1503="Agriculture, Food Industry and Forestry"))>0,"Science",IF((($AL1503="Banking and Finance")+($AL1503="Management and Administration")+($AL1503="Marketing")+($AL1503="Sales")+($AL1503="Entrepreneurship")+($AL1503="Hospitality and Tourism"))>0,"Commerce",IF((($AL1503="Social Sciences and Humanities")+($AL1503="Law Studies")+($AL1503="Education and Training")+($AL1503="Art, Design")+($AL1503="Entertainment and Mass Media")+($AL1503="Community and Social Service")+($AL1503="Personal Care and Services")+($AL1503="Government and Public Administration")+($AL1503="Defence/ Protective Service")+($AL1503="Sports"))>0,"Arts / Humanities","")))) | BD1503: =IF($B1503="","",--(F1503>=10)+--(G1503>=10)+--(H1503>=10)+--(I1503>=10)+--(J1503>=10)+--(K1503>=10)+--(L1503>=10)+--(M1503>=10)+--(N1503>=10)+--(O1503>=10)) | BE1503: =IF($B1503="","",--(AND(F1503<>"",F1503<=8))+--(AND(G1503<>"",G1503<=8))+--(AND(H1503<>"",H1503<=8))+--(AND(I1503<>"",I1503<=8))+--(AND(J1503<>"",J1503<=8))+--(AND(K1503<>"",K1503<=8))+--(AND(L1503<>"",L1503<=8))+--(AND(M1503<>"",M1503<=8))+--(AND(N1503<>"",N1503<=8))+--(AND(O1503<>"",O1503<=8)))

Sheet 2. SUMMARY
B1: SCHOOL SUMMARY
B2: Every number on every sheet respects the class filter below.
D3: min | E3: max
B4: CLASS FILTER | C4: All | D4: =IF(C4="All",1,C4) -> 1 | E4: =IF(C4="All",99,C4) -> 99
A6: HEADCOUNT
B7: Metric | C7: Value
B8: Students in view | C8: =COUNTIFS('1. PASTE DATA'!$B$4:$B$1503,"<>",'1. PASTE DATA'!$C$4:$C$1503,">="&'2. SUMMARY'!$D$4,'1. PASTE DATA'!$C$4:$C$1503,"<="&'2. SUMMARY'!$E$4) -> 0
B9: Girls | C9: =COUNTIFS('1. PASTE DATA'!$E$4:$E$1503,"F",'1. PASTE DATA'!$C$4:$C$1503,">="&'2. SUMMARY'!$D$4,'1. PASTE DATA'!$C$4:$C$1503,"<="&'2. SUMMARY'!$E$4) -> 0
B10: Boys | C10: =COUNTIFS('1. PASTE DATA'!$E$4:$E$1503,"M",'1. PASTE DATA'!$C$4:$C$1503,">="&'2. SUMMARY'!$D$4,'1. PASTE DATA'!$C$4:$C$1503,"<="&'2. SUMMARY'!$E$4) -> 0
B11: Career clarity — students with at least one aspiration that matches their suitability | C11: =IFERROR(ROUND(SUMIFS('1. PASTE DATA'!$BA$4:$BA$1503,'1. PASTE DATA'!$C$4:$C$1503,">="&'2. SUMMARY'!$D$4,'1. PASTE DATA'!$C$4:$C$1503,"<="&'2. SUMMARY'!$E$4)/COUNTIFS('1. PASTE DATA'!$B$4:$B$1503,"<>",'1. PASTE DATA'!$C$4:$C$1503,">="&'2. SUMMARY'!$D$4,'1. PASTE DATA'!$C$4:$C$1503,"<="&'2. SUMMARY'!$E$4)*100,0),0) -> 0
B12: Average matched aspirations per student | C12: =IFERROR(ROUND(SUMIFS('1. PASTE DATA'!$AZ$4:$AZ$1503,'1. PASTE DATA'!$C$4:$C$1503,">="&'2. SUMMARY'!$D$4,'1. PASTE DATA'!$C$4:$C$1503,"<="&'2. SUMMARY'!$E$4)/COUNTIFS('1. PASTE DATA'!$B$4:$B$1503,"<>",'1. PASTE DATA'!$C$4:$C$1503,">="&'2. SUMMARY'!$D$4,'1. PASTE DATA'!$C$4:$C$1503,"<="&'2. SUMMARY'!$E$4),2),0) -> 0
A14: STUDENTS BY CLASS
B15: Class | C15: Students | D15: % of school
B16: Class 6 | C16: =COUNTIFS('1. PASTE DATA'!$C$4:$C$1503,6,'1. PASTE DATA'!$B$4:$B$1503,"<>") -> 0 | D16: =IFERROR(ROUND(C16/SUM($C$16:$C$22)*100,0),0) -> 0
B17: Class 7 | C17: =COUNTIFS('1. PASTE DATA'!$C$4:$C$1503,7,'1. PASTE DATA'!$B$4:$B$1503,"<>") -> 0 | D17: =IFERROR(ROUND(C17/SUM($C$16:$C$22)*100,0),0) -> 0
B18: Class 8 | C18: =COUNTIFS('1. PASTE DATA'!$C$4:$C$1503,8,'1. PASTE DATA'!$B$4:$B$1503,"<>") -> 0 | D18: =IFERROR(ROUND(C18/SUM($C$16:$C$22)*100,0),0) -> 0
B19: Class 9 | C19: =COUNTIFS('1. PASTE DATA'!$C$4:$C$1503,9,'1. PASTE DATA'!$B$4:$B$1503,"<>") -> 0 | D19: =IFERROR(ROUND(C19/SUM($C$16:$C$22)*100,0),0) -> 0
B20: Class 10 | C20: =COUNTIFS('1. PASTE DATA'!$C$4:$C$1503,10,'1. PASTE DATA'!$B$4:$B$1503,"<>") -> 0 | D20: =IFERROR(ROUND(C20/SUM($C$16:$C$22)*100,0),0) -> 0
B21: Class 11 | C21: =COUNTIFS('1. PASTE DATA'!$C$4:$C$1503,11,'1. PASTE DATA'!$B$4:$B$1503,"<>") -> 0 | D21: =IFERROR(ROUND(C21/SUM($C$16:$C$22)*100,0),0) -> 0
B22: Class 12 | C22: =COUNTIFS('1. PASTE DATA'!$C$4:$C$1503,12,'1. PASTE DATA'!$B$4:$B$1503,"<>") -> 0 | D22: =IFERROR(ROUND(C22/SUM($C$16:$C$22)*100,0),0) -> 0
B23: Total | C23: =SUM(C16:C22) -> 0
A25: THE SCHOOL IN ONE LINE | B25: Dominant personality | C25: =INDEX('3. PERSONALITY'!$B$6:$B$11,MATCH(MAX('3. PERSONALITY'!$D$6:$D$11),'3. PERSONALITY'!$D$6:$D$11,0)) -> Doer (Realistic)
B26: Second personality | C26: =INDEX('3. PERSONALITY'!$B$6:$B$11,MATCH(LARGE('3. PERSONALITY'!$D$6:$D$11,2),'3. PERSONALITY'!$D$6:$D$11,0)) -> Doer (Realistic)
B27: Dominant learning style | C27: =INDEX('4. LEARNING STYLE'!$B$6:$B$13,MATCH(MAX('4. LEARNING STYLE'!$C$6:$C$13),'4. LEARNING STYLE'!$C$6:$C$13,0)) -> Body smart (Bodily-Kinesthetic)
B28: Weakest learning style | C28: =INDEX('4. LEARNING STYLE'!$B$6:$B$13,MATCH(MIN('4. LEARNING STYLE'!$C$6:$C$13),'4. LEARNING STYLE'!$C$6:$C$13,0)) -> Body smart (Bodily-Kinesthetic)
B29: Strongest ability | C29: =INDEX('5. ABILITIES'!$B$6:$B$15,MATCH(MAX('5. ABILITIES'!$C$6:$C$15),'5. ABILITIES'!$C$6:$C$15,0)) -> Speed and accuracy
B30: Weakest ability | C30: =INDEX('5. ABILITIES'!$B$6:$B$15,MATCH(MAX('5. ABILITIES'!$D$6:$D$15),'5. ABILITIES'!$D$6:$D$15,0)) -> Speed and accuracy
B31: Top value | C31: =INDEX('6. VALUES'!$B$6:$B$20,MATCH(MAX('6. VALUES'!$C$6:$C$20),'6. VALUES'!$C$6:$C$20,0)) -> Lucrative Salary
B32: Best-fit stream | C32: ='7. CAREER GAP'!$B$6 -> Science
B33: Most-wanted stream | C33: ='7. CAREER GAP'!$B$7 -> Commerce

Sheet 3. PERSONALITY
A1: 3. PERSONALITY
A2: Raw RIASEC average, plus how often each trait lands in a student's top one and top three.
B5: Trait (report label) | C5: Avg raw score | D5: % as top trait | E5: % in top three | F5: Students, top trait | G5: Students, in top three
B6: Doer (Realistic) | C6: =IFERROR(ROUND(AVERAGEIFS('1. PASTE DATA'!$X$4:$X$1503,'1. PASTE DATA'!$C$4:$C$1503,">="&'2. SUMMARY'!$D$4,'1. PASTE DATA'!$C$4:$C$1503,"<="&'2. SUMMARY'!$E$4),1),0) -> 0 | D6: =IFERROR(ROUND((COUNTIFS('1. PASTE DATA'!$AD$4:$AD$1503,"Realistic",'1. PASTE DATA'!$C$4:$C$1503,">="&'2. SUMMARY'!$D$4,'1. PASTE DATA'!$C$4:$C$1503,"<="&'2. SUMMARY'!$E$4))/COUNTIFS('1. PASTE DATA'!$B$4:$B$1503,"<>",'1. PASTE DATA'!$C$4:$C$1503,">="&'2. SUMMARY'!$D$4,'1. PASTE DATA'!$C$4:$C$1503,"<="&'2. SUMMARY'!$E$4)*100,0),0) -> 0 | E6: =IFERROR(ROUND((COUNTIFS('1. PASTE DATA'!$AD$4:$AD$1503,"Realistic",'1. PASTE DATA'!$C$4:$C$1503,">="&'2. SUMMARY'!$D$4,'1. PASTE DATA'!$C$4:$C$1503,"<="&'2. SUMMARY'!$E$4)+COUNTIFS('1. PASTE DATA'!$AE$4:$AE$1503,"Realistic",'1. PASTE DATA'!$C$4:$C$1503,">="&'2. SUMMARY'!$D$4,'1. PASTE DATA'!$C$4:$C$1503,"<="&'2. SUMMARY'!$E$4)+COUNTIFS('1. PASTE DATA'!$AF$4:$AF$1503,"Realistic",'1. PASTE DATA'!$C$4:$C$1503,">="&'2. SUMMARY'!$D$4,'1. PASTE DATA'!$C$4:$C$1503,"<="&'2. SUMMARY'!$E$4))/COUNTIFS('1. PASTE DATA'!$B$4:$B$1503,"<>",'1. PASTE DATA'!$C$4:$C$1503,">="&'2. SUMMARY'!$D$4,'1. PASTE DATA'!$C$4:$C$1503,"<="&'2. SUMMARY'!$E$4)*100,0),0) -> 0 | F6: =COUNTIFS('1. PASTE DATA'!$AD$4:$AD$1503,"Realistic",'1. PASTE DATA'!$C$4:$C$1503,">="&'2. SUMMARY'!$D$4,'1. PASTE DATA'!$C$4:$C$1503,"<="&'2. SUMMARY'!$E$4) -> 0 | G6: =COUNTIFS('1. PASTE DATA'!$AD$4:$AD$1503,"Realistic",'1. PASTE DATA'!$C$4:$C$1503,">="&'2. SUMMARY'!$D$4,'1. PASTE DATA'!$C$4:$C$1503,"<="&'2. SUMMARY'!$E$4)+COUNTIFS('1. PASTE DATA'!$AE$4:$AE$1503,"Realistic",'1. PASTE DATA'!$C$4:$C$1503,">="&'2. SUMMARY'!$D$4,'1. PASTE DATA'!$C$4:$C$1503,"<="&'2. SUMMARY'!$E$4)+COUNTIFS('1. PASTE DATA'!$AF$4:$AF$1503,"Realistic",'1. PASTE DATA'!$C$4:$C$1503,">="&'2. SUMMARY'!$D$4,'1. PASTE DATA'!$C$4:$C$1503,"<="&'2. SUMMARY'!$E$4) -> 0
B7: Thinker (Investigative) | C7: =IFERROR(ROUND(AVERAGEIFS('1. PASTE DATA'!$Y$4:$Y$1503,'1. PASTE DATA'!$C$4:$C$1503,">="&'2. SUMMARY'!$D$4,'1. PASTE DATA'!$C$4:$C$1503,"<="&'2. SUMMARY'!$E$4),1),0) -> 0 | D7: =IFERROR(ROUND((COUNTIFS('1. PASTE DATA'!$AD$4:$AD$1503,"Investigative",'1. PASTE DATA'!$C$4:$C$1503,">="&'2. SUMMARY'!$D$4,'1. PASTE DATA'!$C$4:$C$1503,"<="&'2. SUMMARY'!$E$4))/COUNTIFS('1. PASTE DATA'!$B$4:$B$1503,"<>",'1. PASTE DATA'!$C$4:$C$1503,">="&'2. SUMMARY'!$D$4,'1. PASTE DATA'!$C$4:$C$1503,"<="&'2. SUMMARY'!$E$4)*100,0),0) -> 0 | E7: =IFERROR(ROUND((COUNTIFS('1. PASTE DATA'!$AD$4:$AD$1503,"Investigative",'1. PASTE DATA'!$C$4:$C$1503,">="&'2. SUMMARY'!$D$4,'1. PASTE DATA'!$C$4:$C$1503,"<="&'2. SUMMARY'!$E$4)+COUNTIFS('1. PASTE DATA'!$AE$4:$AE$1503,"Investigative",'1. PASTE DATA'!$C$4:$C$1503,">="&'2. SUMMARY'!$D$4,'1. PASTE DATA'!$C$4:$C$1503,"<="&'2. SUMMARY'!$E$4)+COUNTIFS('1. PASTE DATA'!$AF$4:$AF$1503,"Investigative",'1. PASTE DATA'!$C$4:$C$1503,">="&'2. SUMMARY'!$D$4,'1. PASTE DATA'!$C$4:$C$1503,"<="&'2. SUMMARY'!$E$4))/COUNTIFS('1. PASTE DATA'!$B$4:$B$1503,"<>",'1. PASTE DATA'!$C$4:$C$1503,">="&'2. SUMMARY'!$D$4,'1. PASTE DATA'!$C$4:$C$1503,"<="&'2. SUMMARY'!$E$4)*100,0),0) -> 0 | F7: =COUNTIFS('1. PASTE DATA'!$AD$4:$AD$1503,"Investigative",'1. PASTE DATA'!$C$4:$C$1503,">="&'2. SUMMARY'!$D$4,'1. PASTE DATA'!$C$4:$C$1503,"<="&'2. SUMMARY'!$E$4) -> 0 | G7: =COUNTIFS('1. PASTE DATA'!$AD$4:$AD$1503,"Investigative",'1. PASTE DATA'!$C$4:$C$1503,">="&'2. SUMMARY'!$D$4,'1. PASTE DATA'!$C$4:$C$1503,"<="&'2. SUMMARY'!$E$4)+COUNTIFS('1. PASTE DATA'!$AE$4:$AE$1503,"Investigative",'1. PASTE DATA'!$C$4:$C$1503,">="&'2. SUMMARY'!$D$4,'1. PASTE DATA'!$C$4:$C$1503,"<="&'2. SUMMARY'!$E$4)+COUNTIFS('1. PASTE DATA'!$AF$4:$AF$1503,"Investigative",'1. PASTE DATA'!$C$4:$C$1503,">="&'2. SUMMARY'!$D$4,'1. PASTE DATA'!$C$4:$C$1503,"<="&'2. SUMMARY'!$E$4) -> 0
B8: Creator (Artistic) | C8: =IFERROR(ROUND(AVERAGEIFS('1. PASTE DATA'!$Z$4:$Z$1503,'1. PASTE DATA'!$C$4:$C$1503,">="&'2. SUMMARY'!$D$4,'1. PASTE DATA'!$C$4:$C$1503,"<="&'2. SUMMARY'!$E$4),1),0) -> 0 | D8: =IFERROR(ROUND((COUNTIFS('1. PASTE DATA'!$AD$4:$AD$1503,"Artistic",'1. PASTE DATA'!$C$4:$C$1503,">="&'2. SUMMARY'!$D$4,'1. PASTE DATA'!$C$4:$C$1503,"<="&'2. SUMMARY'!$E$4))/COUNTIFS('1. PASTE DATA'!$B$4:$B$1503,"<>",'1. PASTE DATA'!$C$4:$C$1503,">="&'2. SUMMARY'!$D$4,'1. PASTE DATA'!$C$4:$C$1503,"<="&'2. SUMMARY'!$E$4)*100,0),0) -> 0 | E8: =IFERROR(ROUND((COUNTIFS('1. PASTE DATA'!$AD$4:$AD$1503,"Artistic",'1. PASTE DATA'!$C$4:$C$1503,">="&'2. SUMMARY'!$D$4,'1. PASTE DATA'!$C$4:$C$1503,"<="&'2. SUMMARY'!$E$4)+COUNTIFS('1. PASTE DATA'!$AE$4:$AE$1503,"Artistic",'1. PASTE DATA'!$C$4:$C$1503,">="&'2. SUMMARY'!$D$4,'1. PASTE DATA'!$C$4:$C$1503,"<="&'2. SUMMARY'!$E$4)+COUNTIFS('1. PASTE DATA'!$AF$4:$AF$1503,"Artistic",'1. PASTE DATA'!$C$4:$C$1503,">="&'2. SUMMARY'!$D$4,'1. PASTE DATA'!$C$4:$C$1503,"<="&'2. SUMMARY'!$E$4))/COUNTIFS('1. PASTE DATA'!$B$4:$B$1503,"<>",'1. PASTE DATA'!$C$4:$C$1503,">="&'2. SUMMARY'!$D$4,'1. PASTE DATA'!$C$4:$C$1503,"<="&'2. SUMMARY'!$E$4)*100,0),0) -> 0 | F8: =COUNTIFS('1. PASTE DATA'!$AD$4:$AD$1503,"Artistic",'1. PASTE DATA'!$C$4:$C$1503,">="&'2. SUMMARY'!$D$4,'1. PASTE DATA'!$C$4:$C$1503,"<="&'2. SUMMARY'!$E$4) -> 0 | G8: =COUNTIFS('1. PASTE DATA'!$AD$4:$AD$1503,"Artistic",'1. PASTE DATA'!$C$4:$C$1503,">="&'2. SUMMARY'!$D$4,'1. PASTE DATA'!$C$4:$C$1503,"<="&'2. SUMMARY'!$E$4)+COUNTIFS('1. PASTE DATA'!$AE$4:$AE$1503,"Artistic",'1. PASTE DATA'!$C$4:$C$1503,">="&'2. SUMMARY'!$D$4,'1. PASTE DATA'!$C$4:$C$1503,"<="&'2. SUMMARY'!$E$4)+COUNTIFS('1. PASTE DATA'!$AF$4:$AF$1503,"Artistic",'1. PASTE DATA'!$C$4:$C$1503,">="&'2. SUMMARY'!$D$4,'1. PASTE DATA'!$C$4:$C$1503,"<="&'2. SUMMARY'!$E$4) -> 0
B9: Helper (Social) | C9: =IFERROR(ROUND(AVERAGEIFS('1. PASTE DATA'!$AA$4:$AA$1503,'1. PASTE DATA'!$C$4:$C$1503,">="&'2. SUMMARY'!$D$4,'1. PASTE DATA'!$C$4:$C$1503,"<="&'2. SUMMARY'!$E$4),1),0) -> 0 | D9: =IFERROR(ROUND((COUNTIFS('1. PASTE DATA'!$AD$4:$AD$1503,"Social",'1. PASTE DATA'!$C$4:$C$1503,">="&'2. SUMMARY'!$D$4,'1. PASTE DATA'!$C$4:$C$1503,"<="&'2. SUMMARY'!$E$4))/COUNTIFS('1. PASTE DATA'!$B$4:$B$1503,"<>",'1. PASTE DATA'!$C$4:$C$1503,">="&'2. SUMMARY'!$D$4,'1. PASTE DATA'!$C$4:$C$1503,"<="&'2. SUMMARY'!$E$4)*100,0),0) -> 0 | E9: =IFERROR(ROUND((COUNTIFS('1. PASTE DATA'!$AD$4:$AD$1503,"Social",'1. PASTE DATA'!$C$4:$C$1503,">="&'2. SUMMARY'!$D$4,'1. PASTE DATA'!$C$4:$C$1503,"<="&'2. SUMMARY'!$E$4)+COUNTIFS('1. PASTE DATA'!$AE$4:$AE$1503,"Social",'1. PASTE DATA'!$C$4:$C$1503,">="&'2. SUMMARY'!$D$4,'1. PASTE DATA'!$C$4:$C$1503,"<="&'2. SUMMARY'!$E$4)+COUNTIFS('1. PASTE DATA'!$AF$4:$AF$1503,"Social",'1. PASTE DATA'!$C$4:$C$1503,">="&'2. SUMMARY'!$D$4,'1. PASTE DATA'!$C$4:$C$1503,"<="&'2. SUMMARY'!$E$4))/COUNTIFS('1. PASTE DATA'!$B$4:$B$1503,"<>",'1. PASTE DATA'!$C$4:$C$1503,">="&'2. SUMMARY'!$D$4,'1. PASTE DATA'!$C$4:$C$1503,"<="&'2. SUMMARY'!$E$4)*100,0),0) -> 0 | F9: =COUNTIFS('1. PASTE DATA'!$AD$4:$AD$1503,"Social",'1. PASTE DATA'!$C$4:$C$1503,">="&'2. SUMMARY'!$D$4,'1. PASTE DATA'!$C$4:$C$1503,"<="&'2. SUMMARY'!$E$4) -> 0 | G9: =COUNTIFS('1. PASTE DATA'!$AD$4:$AD$1503,"Social",'1. PASTE DATA'!$C$4:$C$1503,">="&'2. SUMMARY'!$D$4,'1. PASTE DATA'!$C$4:$C$1503,"<="&'2. SUMMARY'!$E$4)+COUNTIFS('1. PASTE DATA'!$AE$4:$AE$1503,"Social",'1. PASTE DATA'!$C$4:$C$1503,">="&'2. SUMMARY'!$D$4,'1. PASTE DATA'!$C$4:$C$1503,"<="&'2. SUMMARY'!$E$4)+COUNTIFS('1. PASTE DATA'!$AF$4:$AF$1503,"Social",'1. PASTE DATA'!$C$4:$C$1503,">="&'2. SUMMARY'!$D$4,'1. PASTE DATA'!$C$4:$C$1503,"<="&'2. SUMMARY'!$E$4) -> 0
B10: Persuader (Enterprising) | C10: =IFERROR(ROUND(AVERAGEIFS('1. PASTE DATA'!$AB$4:$AB$1503,'1. PASTE DATA'!$C$4:$C$1503,">="&'2. SUMMARY'!$D$4,'1. PASTE DATA'!$C$4:$C$1503,"<="&'2. SUMMARY'!$E$4),1),0) -> 0 | D10: =IFERROR(ROUND((COUNTIFS('1. PASTE DATA'!$AD$4:$AD$1503,"Enterprising",'1. PASTE DATA'!$C$4:$C$1503,">="&'2. SUMMARY'!$D$4,'1. PASTE DATA'!$C$4:$C$1503,"<="&'2. SUMMARY'!$E$4))/COUNTIFS('1. PASTE DATA'!$B$4:$B$1503,"<>",'1. PASTE DATA'!$C$4:$C$1503,">="&'2. SUMMARY'!$D$4,'1. PASTE DATA'!$C$4:$C$1503,"<="&'2. SUMMARY'!$E$4)*100,0),0) -> 0 | E10: =IFERROR(ROUND((COUNTIFS('1. PASTE DATA'!$AD$4:$AD$1503,"Enterprising",'1. PASTE DATA'!$C$4:$C$1503,">="&'2. SUMMARY'!$D$4,'1. PASTE DATA'!$C$4:$C$1503,"<="&'2. SUMMARY'!$E$4)+COUNTIFS('1. PASTE DATA'!$AE$4:$AE$1503,"Enterprising",'1. PASTE DATA'!$C$4:$C$1503,">="&'2. SUMMARY'!$D$4,'1. PASTE DATA'!$C$4:$C$1503,"<="&'2. SUMMARY'!$E$4)+COUNTIFS('1. PASTE DATA'!$AF$4:$AF$1503,"Enterprising",'1. PASTE DATA'!$C$4:$C$1503,">="&'2. SUMMARY'!$D$4,'1. PASTE DATA'!$C$4:$C$1503,"<="&'2. SUMMARY'!$E$4))/COUNTIFS('1. PASTE DATA'!$B$4:$B$1503,"<>",'1. PASTE DATA'!$C$4:$C$1503,">="&'2. SUMMARY'!$D$4,'1. PASTE DATA'!$C$4:$C$1503,"<="&'2. SUMMARY'!$E$4)*100,0),0) -> 0 | F10: =COUNTIFS('1. PASTE DATA'!$AD$4:$AD$1503,"Enterprising",'1. PASTE DATA'!$C$4:$C$1503,">="&'2. SUMMARY'!$D$4,'1. PASTE DATA'!$C$4:$C$1503,"<="&'2. SUMMARY'!$E$4) -> 0 | G10: =COUNTIFS('1. PASTE DATA'!$AD$4:$AD$1503,"Enterprising",'1. PASTE DATA'!$C$4:$C$1503,">="&'2. SUMMARY'!$D$4,'1. PASTE DATA'!$C$4:$C$1503,"<="&'2. SUMMARY'!$E$4)+COUNTIFS('1. PASTE DATA'!$AE$4:$AE$1503,"Enterprising",'1. PASTE DATA'!$C$4:$C$1503,">="&'2. SUMMARY'!$D$4,'1. PASTE DATA'!$C$4:$C$1503,"<="&'2. SUMMARY'!$E$4)+COUNTIFS('1. PASTE DATA'!$AF$4:$AF$1503,"Enterprising",'1. PASTE DATA'!$C$4:$C$1503,">="&'2. SUMMARY'!$D$4,'1. PASTE DATA'!$C$4:$C$1503,"<="&'2. SUMMARY'!$E$4) -> 0
B11: Conventional (Conventional) | C11: =IFERROR(ROUND(AVERAGEIFS('1. PASTE DATA'!$AC$4:$AC$1503,'1. PASTE DATA'!$C$4:$C$1503,">="&'2. SUMMARY'!$D$4,'1. PASTE DATA'!$C$4:$C$1503,"<="&'2. SUMMARY'!$E$4),1),0) -> 0 | D11: =IFERROR(ROUND((COUNTIFS('1. PASTE DATA'!$AD$4:$AD$1503,"Conventional",'1. PASTE DATA'!$C$4:$C$1503,">="&'2. SUMMARY'!$D$4,'1. PASTE DATA'!$C$4:$C$1503,"<="&'2. SUMMARY'!$E$4))/COUNTIFS('1. PASTE DATA'!$B$4:$B$1503,"<>",'1. PASTE DATA'!$C$4:$C$1503,">="&'2. SUMMARY'!$D$4,'1. PASTE DATA'!$C$4:$C$1503,"<="&'2. SUMMARY'!$E$4)*100,0),0) -> 0 | E11: =IFERROR(ROUND((COUNTIFS('1. PASTE DATA'!$AD$4:$AD$1503,"Conventional",'1. PASTE DATA'!$C$4:$C$1503,">="&'2. SUMMARY'!$D$4,'1. PASTE DATA'!$C$4:$C$1503,"<="&'2. SUMMARY'!$E$4)+COUNTIFS('1. PASTE DATA'!$AE$4:$AE$1503,"Conventional",'1. PASTE DATA'!$C$4:$C$1503,">="&'2. SUMMARY'!$D$4,'1. PASTE DATA'!$C$4:$C$1503,"<="&'2. SUMMARY'!$E$4)+COUNTIFS('1. PASTE DATA'!$AF$4:$AF$1503,"Conventional",'1. PASTE DATA'!$C$4:$C$1503,">="&'2. SUMMARY'!$D$4,'1. PASTE DATA'!$C$4:$C$1503,"<="&'2. SUMMARY'!$E$4))/COUNTIFS('1. PASTE DATA'!$B$4:$B$1503,"<>",'1. PASTE DATA'!$C$4:$C$1503,">="&'2. SUMMARY'!$D$4,'1. PASTE DATA'!$C$4:$C$1503,"<="&'2. SUMMARY'!$E$4)*100,0),0) -> 0 | F11: =COUNTIFS('1. PASTE DATA'!$AD$4:$AD$1503,"Conventional",'1. PASTE DATA'!$C$4:$C$1503,">="&'2. SUMMARY'!$D$4,'1. PASTE DATA'!$C$4:$C$1503,"<="&'2. SUMMARY'!$E$4) -> 0 | G11: =COUNTIFS('1. PASTE DATA'!$AD$4:$AD$1503,"Conventional",'1. PASTE DATA'!$C$4:$C$1503,">="&'2. SUMMARY'!$D$4,'1. PASTE DATA'!$C$4:$C$1503,"<="&'2. SUMMARY'!$E$4)+COUNTIFS('1. PASTE DATA'!$AE$4:$AE$1503,"Conventional",'1. PASTE DATA'!$C$4:$C$1503,">="&'2. SUMMARY'!$D$4,'1. PASTE DATA'!$C$4:$C$1503,"<="&'2. SUMMARY'!$E$4)+COUNTIFS('1. PASTE DATA'!$AF$4:$AF$1503,"Conventional",'1. PASTE DATA'!$C$4:$C$1503,">="&'2. SUMMARY'!$D$4,'1. PASTE DATA'!$C$4:$C$1503,"<="&'2. SUMMARY'!$E$4) -> 0
B12: Total | D12: =SUM(D6:D11) -> 0
B14: SPREAD — how concentrated the school is
B15: Highest trait share | C15: =MAX(D6:D11) -> 0
B16: Lowest trait share | C16: =MIN(D6:D11) -> 0
B17: Spread (highest minus lowest) | C17: =MAX(D6:D11)-MIN(D6:D11) -> 0
B18: Traits above 20% | C18: =COUNTIF(D6:D11,">=20") -> 0

Sheet 4. LEARNING STYLE
A1: 4. LEARNING STYLE
A2: Multiple-intelligence profile. 'Strong' is a score of 10 or more out of 12; 'low' is 8 or under.
B5: Intelligence | C5: % strong | D5: % low | E5: Avg score | F5: Students strong | G5: Students low
B6: Body smart (Bodily-Kinesthetic) | C6: =IFERROR(ROUND((COUNTIFS('1. PASTE DATA'!$P$4:$P$1503,">=10",'1. PASTE DATA'!$C$4:$C$1503,">="&'2. SUMMARY'!$D$4,'1. PASTE DATA'!$C$4:$C$1503,"<="&'2. SUMMARY'!$E$4))/COUNTIFS('1. PASTE DATA'!$B$4:$B$1503,"<>",'1. PASTE DATA'!$C$4:$C$1503,">="&'2. SUMMARY'!$D$4,'1. PASTE DATA'!$C$4:$C$1503,"<="&'2. SUMMARY'!$E$4)*100,0),0) -> 0 | D6: =IFERROR(ROUND((COUNTIFS('1. PASTE DATA'!$P$4:$P$1503,"<=8",'1. PASTE DATA'!$C$4:$C$1503,">="&'2. SUMMARY'!$D$4,'1. PASTE DATA'!$C$4:$C$1503,"<="&'2. SUMMARY'!$E$4))/COUNTIFS('1. PASTE DATA'!$B$4:$B$1503,"<>",'1. PASTE DATA'!$C$4:$C$1503,">="&'2. SUMMARY'!$D$4,'1. PASTE DATA'!$C$4:$C$1503,"<="&'2. SUMMARY'!$E$4)*100,0),0) -> 0 | E6: =IFERROR(ROUND(AVERAGEIFS('1. PASTE DATA'!$P$4:$P$1503,'1. PASTE DATA'!$C$4:$C$1503,">="&'2. SUMMARY'!$D$4,'1. PASTE DATA'!$C$4:$C$1503,"<="&'2. SUMMARY'!$E$4),1),0) -> 0 | F6: =COUNTIFS('1. PASTE DATA'!$P$4:$P$1503,">=10",'1. PASTE DATA'!$C$4:$C$1503,">="&'2. SUMMARY'!$D$4,'1. PASTE DATA'!$C$4:$C$1503,"<="&'2. SUMMARY'!$E$4) -> 0 | G6: =COUNTIFS('1. PASTE DATA'!$P$4:$P$1503,"<=8",'1. PASTE DATA'!$C$4:$C$1503,">="&'2. SUMMARY'!$D$4,'1. PASTE DATA'!$C$4:$C$1503,"<="&'2. SUMMARY'!$E$4) -> 0
B7: People smart (Interpersonal) | C7: =IFERROR(ROUND((COUNTIFS('1. PASTE DATA'!$Q$4:$Q$1503,">=10",'1. PASTE DATA'!$C$4:$C$1503,">="&'2. SUMMARY'!$D$4,'1. PASTE DATA'!$C$4:$C$1503,"<="&'2. SUMMARY'!$E$4))/COUNTIFS('1. PASTE DATA'!$B$4:$B$1503,"<>",'1. PASTE DATA'!$C$4:$C$1503,">="&'2. SUMMARY'!$D$4,'1. PASTE DATA'!$C$4:$C$1503,"<="&'2. SUMMARY'!$E$4)*100,0),0) -> 0 | D7: =IFERROR(ROUND((COUNTIFS('1. PASTE DATA'!$Q$4:$Q$1503,"<=8",'1. PASTE DATA'!$C$4:$C$1503,">="&'2. SUMMARY'!$D$4,'1. PASTE DATA'!$C$4:$C$1503,"<="&'2. SUMMARY'!$E$4))/COUNTIFS('1. PASTE DATA'!$B$4:$B$1503,"<>",'1. PASTE DATA'!$C$4:$C$1503,">="&'2. SUMMARY'!$D$4,'1. PASTE DATA'!$C$4:$C$1503,"<="&'2. SUMMARY'!$E$4)*100,0),0) -> 0 | E7: =IFERROR(ROUND(AVERAGEIFS('1. PASTE DATA'!$Q$4:$Q$1503,'1. PASTE DATA'!$C$4:$C$1503,">="&'2. SUMMARY'!$D$4,'1. PASTE DATA'!$C$4:$C$1503,"<="&'2. SUMMARY'!$E$4),1),0) -> 0 | F7: =COUNTIFS('1. PASTE DATA'!$Q$4:$Q$1503,">=10",'1. PASTE DATA'!$C$4:$C$1503,">="&'2. SUMMARY'!$D$4,'1. PASTE DATA'!$C$4:$C$1503,"<="&'2. SUMMARY'!$E$4) -> 0 | G7: =COUNTIFS('1. PASTE DATA'!$Q$4:$Q$1503,"<=8",'1. PASTE DATA'!$C$4:$C$1503,">="&'2. SUMMARY'!$D$4,'1. PASTE DATA'!$C$4:$C$1503,"<="&'2. SUMMARY'!$E$4) -> 0
B8: Self smart (Intrapersonal) | C8: =IFERROR(ROUND((COUNTIFS('1. PASTE DATA'!$R$4:$R$1503,">=10",'1. PASTE DATA'!$C$4:$C$1503,">="&'2. SUMMARY'!$D$4,'1. PASTE DATA'!$C$4:$C$1503,"<="&'2. SUMMARY'!$E$4))/COUNTIFS('1. PASTE DATA'!$B$4:$B$1503,"<>",'1. PASTE DATA'!$C$4:$C$1503,">="&'2. SUMMARY'!$D$4,'1. PASTE DATA'!$C$4:$C$1503,"<="&'2. SUMMARY'!$E$4)*100,0),0) -> 0 | D8: =IFERROR(ROUND((COUNTIFS('1. PASTE DATA'!$R$4:$R$1503,"<=8",'1. PASTE DATA'!$C$4:$C$1503,">="&'2. SUMMARY'!$D$4,'1. PASTE DATA'!$C$4:$C$1503,"<="&'2. SUMMARY'!$E$4))/COUNTIFS('1. PASTE DATA'!$B$4:$B$1503,"<>",'1. PASTE DATA'!$C$4:$C$1503,">="&'2. SUMMARY'!$D$4,'1. PASTE DATA'!$C$4:$C$1503,"<="&'2. SUMMARY'!$E$4)*100,0),0) -> 0 | E8: =IFERROR(ROUND(AVERAGEIFS('1. PASTE DATA'!$R$4:$R$1503,'1. PASTE DATA'!$C$4:$C$1503,">="&'2. SUMMARY'!$D$4,'1. PASTE DATA'!$C$4:$C$1503,"<="&'2. SUMMARY'!$E$4),1),0) -> 0 | F8: =COUNTIFS('1. PASTE DATA'!$R$4:$R$1503,">=10",'1. PASTE DATA'!$C$4:$C$1503,">="&'2. SUMMARY'!$D$4,'1. PASTE DATA'!$C$4:$C$1503,"<="&'2. SUMMARY'!$E$4) -> 0 | G8: =COUNTIFS('1. PASTE DATA'!$R$4:$R$1503,"<=8",'1. PASTE DATA'!$C$4:$C$1503,">="&'2. SUMMARY'!$D$4,'1. PASTE DATA'!$C$4:$C$1503,"<="&'2. SUMMARY'!$E$4) -> 0
B9: Word smart (Linguistic) | C9: =IFERROR(ROUND((COUNTIFS('1. PASTE DATA'!$S$4:$S$1503,">=10",'1. PASTE DATA'!$C$4:$C$1503,">="&'2. SUMMARY'!$D$4,'1. PASTE DATA'!$C$4:$C$1503,"<="&'2. SUMMARY'!$E$4))/COUNTIFS('1. PASTE DATA'!$B$4:$B$1503,"<>",'1. PASTE DATA'!$C$4:$C$1503,">="&'2. SUMMARY'!$D$4,'1. PASTE DATA'!$C$4:$C$1503,"<="&'2. SUMMARY'!$E$4)*100,0),0) -> 0 | D9: =IFERROR(ROUND((COUNTIFS('1. PASTE DATA'!$S$4:$S$1503,"<=8",'1. PASTE DATA'!$C$4:$C$1503,">="&'2. SUMMARY'!$D$4,'1. PASTE DATA'!$C$4:$C$1503,"<="&'2. SUMMARY'!$E$4))/COUNTIFS('1. PASTE DATA'!$B$4:$B$1503,"<>",'1. PASTE DATA'!$C$4:$C$1503,">="&'2. SUMMARY'!$D$4,'1. PASTE DATA'!$C$4:$C$1503,"<="&'2. SUMMARY'!$E$4)*100,0),0) -> 0 | E9: =IFERROR(ROUND(AVERAGEIFS('1. PASTE DATA'!$S$4:$S$1503,'1. PASTE DATA'!$C$4:$C$1503,">="&'2. SUMMARY'!$D$4,'1. PASTE DATA'!$C$4:$C$1503,"<="&'2. SUMMARY'!$E$4),1),0) -> 0 | F9: =COUNTIFS('1. PASTE DATA'!$S$4:$S$1503,">=10",'1. PASTE DATA'!$C$4:$C$1503,">="&'2. SUMMARY'!$D$4,'1. PASTE DATA'!$C$4:$C$1503,"<="&'2. SUMMARY'!$E$4) -> 0 | G9: =COUNTIFS('1. PASTE DATA'!$S$4:$S$1503,"<=8",'1. PASTE DATA'!$C$4:$C$1503,">="&'2. SUMMARY'!$D$4,'1. PASTE DATA'!$C$4:$C$1503,"<="&'2. SUMMARY'!$E$4) -> 0
B10: Logic smart (Logical-Mathematical) | C10: =IFERROR(ROUND((COUNTIFS('1. PASTE DATA'!$T$4:$T$1503,">=10",'1. PASTE DATA'!$C$4:$C$1503,">="&'2. SUMMARY'!$D$4,'1. PASTE DATA'!$C$4:$C$1503,"<="&'2. SUMMARY'!$E$4))/COUNTIFS('1. PASTE DATA'!$B$4:$B$1503,"<>",'1. PASTE DATA'!$C$4:$C$1503,">="&'2. SUMMARY'!$D$4,'1. PASTE DATA'!$C$4:$C$1503,"<="&'2. SUMMARY'!$E$4)*100,0),0) -> 0 | D10: =IFERROR(ROUND((COUNTIFS('1. PASTE DATA'!$T$4:$T$1503,"<=8",'1. PASTE DATA'!$C$4:$C$1503,">="&'2. SUMMARY'!$D$4,'1. PASTE DATA'!$C$4:$C$1503,"<="&'2. SUMMARY'!$E$4))/COUNTIFS('1. PASTE DATA'!$B$4:$B$1503,"<>",'1. PASTE DATA'!$C$4:$C$1503,">="&'2. SUMMARY'!$D$4,'1. PASTE DATA'!$C$4:$C$1503,"<="&'2. SUMMARY'!$E$4)*100,0),0) -> 0 | E10: =IFERROR(ROUND(AVERAGEIFS('1. PASTE DATA'!$T$4:$T$1503,'1. PASTE DATA'!$C$4:$C$1503,">="&'2. SUMMARY'!$D$4,'1. PASTE DATA'!$C$4:$C$1503,"<="&'2. SUMMARY'!$E$4),1),0) -> 0 | F10: =COUNTIFS('1. PASTE DATA'!$T$4:$T$1503,">=10",'1. PASTE DATA'!$C$4:$C$1503,">="&'2. SUMMARY'!$D$4,'1. PASTE DATA'!$C$4:$C$1503,"<="&'2. SUMMARY'!$E$4) -> 0 | G10: =COUNTIFS('1. PASTE DATA'!$T$4:$T$1503,"<=8",'1. PASTE DATA'!$C$4:$C$1503,">="&'2. SUMMARY'!$D$4,'1. PASTE DATA'!$C$4:$C$1503,"<="&'2. SUMMARY'!$E$4) -> 0
B11: Music smart (Musical) | C11: =IFERROR(ROUND((COUNTIFS('1. PASTE DATA'!$U$4:$U$1503,">=10",'1. PASTE DATA'!$C$4:$C$1503,">="&'2. SUMMARY'!$D$4,'1. PASTE DATA'!$C$4:$C$1503,"<="&'2. SUMMARY'!$E$4))/COUNTIFS('1. PASTE DATA'!$B$4:$B$1503,"<>",'1. PASTE DATA'!$C$4:$C$1503,">="&'2. SUMMARY'!$D$4,'1. PASTE DATA'!$C$4:$C$1503,"<="&'2. SUMMARY'!$E$4)*100,0),0) -> 0 | D11: =IFERROR(ROUND((COUNTIFS('1. PASTE DATA'!$U$4:$U$1503,"<=8",'1. PASTE DATA'!$C$4:$C$1503,">="&'2. SUMMARY'!$D$4,'1. PASTE DATA'!$C$4:$C$1503,"<="&'2. SUMMARY'!$E$4))/COUNTIFS('1. PASTE DATA'!$B$4:$B$1503,"<>",'1. PASTE DATA'!$C$4:$C$1503,">="&'2. SUMMARY'!$D$4,'1. PASTE DATA'!$C$4:$C$1503,"<="&'2. SUMMARY'!$E$4)*100,0),0) -> 0 | E11: =IFERROR(ROUND(AVERAGEIFS('1. PASTE DATA'!$U$4:$U$1503,'1. PASTE DATA'!$C$4:$C$1503,">="&'2. SUMMARY'!$D$4,'1. PASTE DATA'!$C$4:$C$1503,"<="&'2. SUMMARY'!$E$4),1),0) -> 0 | F11: =COUNTIFS('1. PASTE DATA'!$U$4:$U$1503,">=10",'1. PASTE DATA'!$C$4:$C$1503,">="&'2. SUMMARY'!$D$4,'1. PASTE DATA'!$C$4:$C$1503,"<="&'2. SUMMARY'!$E$4) -> 0 | G11: =COUNTIFS('1. PASTE DATA'!$U$4:$U$1503,"<=8",'1. PASTE DATA'!$C$4:$C$1503,">="&'2. SUMMARY'!$D$4,'1. PASTE DATA'!$C$4:$C$1503,"<="&'2. SUMMARY'!$E$4) -> 0
B12: Picture smart (Visual-Spatial) | C12: =IFERROR(ROUND((COUNTIFS('1. PASTE DATA'!$V$4:$V$1503,">=10",'1. PASTE DATA'!$C$4:$C$1503,">="&'2. SUMMARY'!$D$4,'1. PASTE DATA'!$C$4:$C$1503,"<="&'2. SUMMARY'!$E$4))/COUNTIFS('1. PASTE DATA'!$B$4:$B$1503,"<>",'1. PASTE DATA'!$C$4:$C$1503,">="&'2. SUMMARY'!$D$4,'1. PASTE DATA'!$C$4:$C$1503,"<="&'2. SUMMARY'!$E$4)*100,0),0) -> 0 | D12: =IFERROR(ROUND((COUNTIFS('1. PASTE DATA'!$V$4:$V$1503,"<=8",'1. PASTE DATA'!$C$4:$C$1503,">="&'2. SUMMARY'!$D$4,'1. PASTE DATA'!$C$4:$C$1503,"<="&'2. SUMMARY'!$E$4))/COUNTIFS('1. PASTE DATA'!$B$4:$B$1503,"<>",'1. PASTE DATA'!$C$4:$C$1503,">="&'2. SUMMARY'!$D$4,'1. PASTE DATA'!$C$4:$C$1503,"<="&'2. SUMMARY'!$E$4)*100,0),0) -> 0 | E12: =IFERROR(ROUND(AVERAGEIFS('1. PASTE DATA'!$V$4:$V$1503,'1. PASTE DATA'!$C$4:$C$1503,">="&'2. SUMMARY'!$D$4,'1. PASTE DATA'!$C$4:$C$1503,"<="&'2. SUMMARY'!$E$4),1),0) -> 0 | F12: =COUNTIFS('1. PASTE DATA'!$V$4:$V$1503,">=10",'1. PASTE DATA'!$C$4:$C$1503,">="&'2. SUMMARY'!$D$4,'1. PASTE DATA'!$C$4:$C$1503,"<="&'2. SUMMARY'!$E$4) -> 0 | G12: =COUNTIFS('1. PASTE DATA'!$V$4:$V$1503,"<=8",'1. PASTE DATA'!$C$4:$C$1503,">="&'2. SUMMARY'!$D$4,'1. PASTE DATA'!$C$4:$C$1503,"<="&'2. SUMMARY'!$E$4) -> 0
B13: Nature smart (Naturalistic) | C13: =IFERROR(ROUND((COUNTIFS('1. PASTE DATA'!$W$4:$W$1503,">=10",'1. PASTE DATA'!$C$4:$C$1503,">="&'2. SUMMARY'!$D$4,'1. PASTE DATA'!$C$4:$C$1503,"<="&'2. SUMMARY'!$E$4))/COUNTIFS('1. PASTE DATA'!$B$4:$B$1503,"<>",'1. PASTE DATA'!$C$4:$C$1503,">="&'2. SUMMARY'!$D$4,'1. PASTE DATA'!$C$4:$C$1503,"<="&'2. SUMMARY'!$E$4)*100,0),0) -> 0 | D13: =IFERROR(ROUND((COUNTIFS('1. PASTE DATA'!$W$4:$W$1503,"<=8",'1. PASTE DATA'!$C$4:$C$1503,">="&'2. SUMMARY'!$D$4,'1. PASTE DATA'!$C$4:$C$1503,"<="&'2. SUMMARY'!$E$4))/COUNTIFS('1. PASTE DATA'!$B$4:$B$1503,"<>",'1. PASTE DATA'!$C$4:$C$1503,">="&'2. SUMMARY'!$D$4,'1. PASTE DATA'!$C$4:$C$1503,"<="&'2. SUMMARY'!$E$4)*100,0),0) -> 0 | E13: =IFERROR(ROUND(AVERAGEIFS('1. PASTE DATA'!$W$4:$W$1503,'1. PASTE DATA'!$C$4:$C$1503,">="&'2. SUMMARY'!$D$4,'1. PASTE DATA'!$C$4:$C$1503,"<="&'2. SUMMARY'!$E$4),1),0) -> 0 | F13: =COUNTIFS('1. PASTE DATA'!$W$4:$W$1503,">=10",'1. PASTE DATA'!$C$4:$C$1503,">="&'2. SUMMARY'!$D$4,'1. PASTE DATA'!$C$4:$C$1503,"<="&'2. SUMMARY'!$E$4) -> 0 | G13: =COUNTIFS('1. PASTE DATA'!$W$4:$W$1503,"<=8",'1. PASTE DATA'!$C$4:$C$1503,">="&'2. SUMMARY'!$D$4,'1. PASTE DATA'!$C$4:$C$1503,"<="&'2. SUMMARY'!$E$4) -> 0

Sheet 5. ABILITIES
A1: 5. ABILITIES
A2: Strong = 10 or more out of 12. Low = 8 or under. The gap column is how much bigger the weak group is than the strong group.
B5: Ability | C5: % strong | D5: % low | E5: Gap (low minus strong) | F5: Avg score | G5: Students strong | H5: Students low
B6: Speed and accuracy | C6: =IFERROR(ROUND((COUNTIFS('1. PASTE DATA'!$F$4:$F$1503,">=10",'1. PASTE DATA'!$C$4:$C$1503,">="&'2. SUMMARY'!$D$4,'1. PASTE DATA'!$C$4:$C$1503,"<="&'2. SUMMARY'!$E$4))/COUNTIFS('1. PASTE DATA'!$B$4:$B$1503,"<>",'1. PASTE DATA'!$C$4:$C$1503,">="&'2. SUMMARY'!$D$4,'1. PASTE DATA'!$C$4:$C$1503,"<="&'2. SUMMARY'!$E$4)*100,0),0) -> 0 | D6: =IFERROR(ROUND((COUNTIFS('1. PASTE DATA'!$F$4:$F$1503,"<=8",'1. PASTE DATA'!$C$4:$C$1503,">="&'2. SUMMARY'!$D$4,'1. PASTE DATA'!$C$4:$C$1503,"<="&'2. SUMMARY'!$E$4))/COUNTIFS('1. PASTE DATA'!$B$4:$B$1503,"<>",'1. PASTE DATA'!$C$4:$C$1503,">="&'2. SUMMARY'!$D$4,'1. PASTE DATA'!$C$4:$C$1503,"<="&'2. SUMMARY'!$E$4)*100,0),0) -> 0 | E6: =D6-C6 -> 0 | F6: =IFERROR(ROUND(AVERAGEIFS('1. PASTE DATA'!$F$4:$F$1503,'1. PASTE DATA'!$C$4:$C$1503,">="&'2. SUMMARY'!$D$4,'1. PASTE DATA'!$C$4:$C$1503,"<="&'2. SUMMARY'!$E$4),1),0) -> 0 | G6: =COUNTIFS('1. PASTE DATA'!$F$4:$F$1503,">=10",'1. PASTE DATA'!$C$4:$C$1503,">="&'2. SUMMARY'!$D$4,'1. PASTE DATA'!$C$4:$C$1503,"<="&'2. SUMMARY'!$E$4) -> 0 | H6: =COUNTIFS('1. PASTE DATA'!$F$4:$F$1503,"<=8",'1. PASTE DATA'!$C$4:$C$1503,">="&'2. SUMMARY'!$D$4,'1. PASTE DATA'!$C$4:$C$1503,"<="&'2. SUMMARY'!$E$4) -> 0
B7: Computational | C7: =IFERROR(ROUND((COUNTIFS('1. PASTE DATA'!$G$4:$G$1503,">=10",'1. PASTE DATA'!$C$4:$C$1503,">="&'2. SUMMARY'!$D$4,'1. PASTE DATA'!$C$4:$C$1503,"<="&'2. SUMMARY'!$E$4))/COUNTIFS('1. PASTE DATA'!$B$4:$B$1503,"<>",'1. PASTE DATA'!$C$4:$C$1503,">="&'2. SUMMARY'!$D$4,'1. PASTE DATA'!$C$4:$C$1503,"<="&'2. SUMMARY'!$E$4)*100,0),0) -> 0 | D7: =IFERROR(ROUND((COUNTIFS('1. PASTE DATA'!$G$4:$G$1503,"<=8",'1. PASTE DATA'!$C$4:$C$1503,">="&'2. SUMMARY'!$D$4,'1. PASTE DATA'!$C$4:$C$1503,"<="&'2. SUMMARY'!$E$4))/COUNTIFS('1. PASTE DATA'!$B$4:$B$1503,"<>",'1. PASTE DATA'!$C$4:$C$1503,">="&'2. SUMMARY'!$D$4,'1. PASTE DATA'!$C$4:$C$1503,"<="&'2. SUMMARY'!$E$4)*100,0),0) -> 0 | E7: =D7-C7 -> 0 | F7: =IFERROR(ROUND(AVERAGEIFS('1. PASTE DATA'!$G$4:$G$1503,'1. PASTE DATA'!$C$4:$C$1503,">="&'2. SUMMARY'!$D$4,'1. PASTE DATA'!$C$4:$C$1503,"<="&'2. SUMMARY'!$E$4),1),0) -> 0 | G7: =COUNTIFS('1. PASTE DATA'!$G$4:$G$1503,">=10",'1. PASTE DATA'!$C$4:$C$1503,">="&'2. SUMMARY'!$D$4,'1. PASTE DATA'!$C$4:$C$1503,"<="&'2. SUMMARY'!$E$4) -> 0 | H7: =COUNTIFS('1. PASTE DATA'!$G$4:$G$1503,"<=8",'1. PASTE DATA'!$C$4:$C$1503,">="&'2. SUMMARY'!$D$4,'1. PASTE DATA'!$C$4:$C$1503,"<="&'2. SUMMARY'!$E$4) -> 0
